Workbook

Sheet data
A1: id | B1: kode_provinsi | C1: nama_provinsi | D1: pdrb_per_kapita | E1: satuan | F1: tahun | H1: proper_province
A2: 1 | B2: 11 | C2: ACEH | D2: 26851.88 | E2: RIBU RUPIAH | F2: 2016 | H2: =PROPER(tabledata[[#This Row],[nama_provinsi]]) -> Aceh
A3: 2 | B3: 12 | C3: SUMATERA UTARA | D3: 44392.46 | E3: RIBU RUPIAH | F3: 2016 | H3: =PROPER(tabledata[[#This Row],[nama_provinsi]]) -> Sumatera Utara
A4: 3 | B4: 13 | C4: SUMATERA BARAT | D4: 37284.56 | E4: RIBU RUPIAH | F4: 2016 | H4: =PROPER(tabledata[[#This Row],[nama_provinsi]]) -> Sumatera Barat
A5: 4 | B5: 14 | C5: RIAU | D5: 104861.11 | E5: RIBU RUPIAH | F5: 2016 | H5: =PROPER(tabledata[[#This Row],[nama_provinsi]]) -> Riau
A6: 5 | B6: 15 | C6: JAMBI | D6: 49494.98 | E6: RIBU RUPIAH | F6: 2016 | H6: =PROPER(tabledata[[#This Row],[nama_provinsi]]) -> Jambi
A7: 6 | B7: 16 | C7: SUMATERA SELATAN | D7: 43361.26 | E7: RIBU RUPIAH | F7: 2016 | H7: =PROPER(tabledata[[#This Row],[nama_provinsi]]) -> Sumatera Selatan
A8: 7 | B8: 17 | C8: BENGKULU | D8: 29076.22 | E8: RIBU RUPIAH | F8: 2016 | H8: =PROPER(tabledata[[#This Row],[nama_provinsi]]) -> Bengkulu
A9: 8 | B9: 18 | C9: LAMPUNG | D9: 34053.97 | E9: RIBU RUPIAH | F9: 2016 | H9: =PROPER(tabledata[[#This Row],[nama_provinsi]]) -> Lampung
A10: 9 | B10: 19 | C10: KEPULAUAN BANGKA BELITUNG | D10: 46402.47 | E10: RIBU RUPIAH | F10: 2016 | H10: =PROPER(tabledata[[#This Row],[nama_provinsi]]) -> Kepulauan Bangka Belitung
A11: 10 | B11: 21 | C11: KEPULAUAN RIAU | D11: 106503.78 | E11: RIBU RUPIAH | F11: 2016 | H11: =PROPER(tabledata[[#This Row],[nama_provinsi]]) -> Kepulauan Riau
A12: 11 | B12: 31 | C12: DKI JAKARTA | D12: 210075.09 | E12: RIBU RUPIAH | F12: 2016 | H12: DKI Jakarta
A13: 12 | B13: 32 | C13: JAWA BARAT | D13: 34893.62 | E13: RIBU RUPIAH | F13: 2016 | H13: =PROPER(tabledata[[#This Row],[nama_provinsi]]) -> Jawa Barat
A14: 13 | B14: 33 | C14: JAWA TENGAH | D14: 31961.95 | E14: RIBU RUPIAH | F14: 2016 | H14: =PROPER(tabledata[[#This Row],[nama_provinsi]]) -> Jawa Tengah
A15: 14 | B15: 34 | C15: DI YOGYAKARTA | D15: 29552.53 | E15: RIBU RUPIAH | F15: 2016 | H15: DI Yogyakarta
A16: 15 | B16: 35 | C16: JAWA TIMUR | D16: 47491.52 | E16: RIBU RUPIAH | F16: 2016 | H16: =PROPER(tabledata[[#This Row],[nama_provinsi]]) -> Jawa Timur
A17: 16 | B17: 36 | C17: BANTEN | D17: 42439.73 | E17: RIBU RUPIAH | F17: 2016 | H17: =PROPER(tabledata[[#This Row],[nama_provinsi]]) -> Banten
A18: 17 | B18: 51 | C18: BALI | D18: 46211.04 | E18: RIBU RUPIAH | F18: 2016 | H18: =PROPER(tabledata[[#This Row],[nama_provinsi]]) -> Bali
A19: 18 | B19: 52 | C19: NUSA TENGGARA BARAT | D19: 23786.95 | E19: RIBU RUPIAH | F19: 2016 | H19: =PROPER(tabledata[[#This Row],[nama_provinsi]]) -> Nusa Tenggara Barat
A20: 19 | B20: 53 | C20: NUSA TENGGARA TIMUR | D20: 16093.51 | E20: RIBU RUPIAH | F20: 2016 | H20: =PROPER(tabledata[[#This Row],[nama_provinsi]]) -> Nusa Tenggara Timur
A21: 20 | B21: 61 | C21: KALIMANTAN BARAT | D21: 33190.65 | E21: RIBU RUPIAH | F21: 2016 | H21: =PROPER(tabledata[[#This Row],[nama_provinsi]]) -> Kalimantan Barat
A22: 21 | B22: 62 | C22: KALIMANTAN TENGAH | D22: 43905.33 | E22: RIBU RUPIAH | F22: 2016 | H22: =PROPER(tabledata[[#This Row],[nama_provinsi]]) -> Kalimantan Tengah
A23: 22 | B23: 63 | C23: KALIMANTAN SELATAN | D23: 36022.98 | E23: RIBU RUPIAH | F23: 2016 | H23: =PROPER(tabledata[[#This Row],[nama_provinsi]]) -> Kalimantan Selatan
A24: 23 | B24: 64 | C24: KALIMANTAN TIMUR | D24: 145343.19 | E24: RIBU RUPIAH | F24: 2016 | H24: =PROPER(tabledata[[#This Row],[nama_provinsi]]) -> Kalimantan Timur
A25: 24 | B25: 65 | C25: KALIMANTAN UTARA | D25: 99112.33 | E25: RIBU RUPIAH | F25: 2016 | H25: =PROPER(tabledata[[#This Row],[nama_provinsi]]) -> Kalimantan Utara
A26: 25 | B26: 71 | C26: SULAWESI UTARA | D26: 41246.25 | E26: RIBU RUPIAH | F26: 2016 | H26: =PROPER(tabledata[[#This Row],[nama_provinsi]]) -> Sulawesi Utara
A27: 26 | B27: 72 | C27: SULAWESI TENGAH | D27: 41082.04 | E27: RIBU RUPIAH | F27: 2016 | H27: =PROPER(tabledata[[#This Row],[nama_provinsi]]) -> Sulawesi Tengah
... A69: 68 | B69: 94 | C69: PAPUA | D69: 57864.13 | E69: RIBU RUPIAH | F69: 2017 | H69: =PROPER(tabledata[[#This Row],[nama_provinsi]]) -> Papua
A70: 69 | B70: 11 | C70: ACEH | D70: 29521.25 | E70: RIBU RUPIAH | F70: 2018
A71: 70 | B71: 12 | C71: SUMATERA UTARA | D71: 51427.49 | E71: RIBU RUPIAH | F71: 2018
A72: 71 | B72: 13 | C72: SUMATERA BARAT | D72: 42802.66 | E72: RIBU RUPIAH | F72: 2018
A73: 72 | B73: 14 | C73: RIAU | D73: 110384.9 | E73: RIBU RUPIAH | F73: 2018
A74: 73 | B74: 15 | C74: JAMBI | D74: 58224.89 | E74: RIBU RUPIAH | F74: 2018
A75: 74 | B75: 16 | C75: SUMATERA SELATAN | D75: 50104.67 | E75: RIBU RUPIAH | F75: 2018
A76: 75 | B76: 17 | C76: BENGKULU | D76: 33822.13 | E76: RIBU RUPIAH | F76: 2018
A77: 76 | B77: 18 | C77: LAMPUNG | D77: 39716.46 | E77: RIBU RUPIAH | F77: 2018
A78: 77 | B78: 19 | C78: KEPULAUAN BANGKA BELITUNG | D78: 50081.95 | E78: RIBU RUPIAH | F78: 2018
A79: 78 | B79: 21 | C79: KEPULAUAN RIAU | D79: 116461.4 | E79: RIBU RUPIAH | F79: 2018
A80: 79 | B80: 31 | C80: DKI JAKARTA | D80: 247678.49 | E80: RIBU RUPIAH | F80: 2018
A81: 80 | B81: 32 | C81: JAWA BARAT | D81: 40272.64 | E81: RIBU RUPIAH | F81: 2018
...

Sheet OWID (ID)
A1: Copy of OWID data for Indonesia Filter
A2: country | B2: year | C2: iso_code | D2: population | E2: gdp | F2: biofuel_cons_change_pct | G2: biofuel_cons_change_twh | H2: biofuel_cons_per_capita | I2: biofuel_consumption | J2: biofuel_elec_per_capita | K2: biofuel_electricity | L2: biofuel_share_elec | M2: biofuel_share_energy | N2: carbon_intensity_elec | O2: coal_cons_change_pct | P2: coal_cons_change_twh | Q2: coal_cons_per_capita | R2: coal_consumption | S2: coal_elec_per_capita | T2: coal_electricity | U2: coal_prod_change_pct | V2: coal_prod_change_twh | W2: coal_prod_per_capita | X2: coal_production | Y2: coal_share_elec | Z2: coal_share_energy | AA2: electricity_demand | AB2: electricity_demand_per_capita | AC2: electricity_generation | AD2: electricity_share_energy | AE2: energy_cons_change_pct | AF2: energy_cons_change_twh | AG2: energy_per_capita | AH2: energy_per_gdp | AI2: fossil_cons_change_pct | AJ2: fossil_cons_change_twh | AK2: fossil_elec_per_capita | AL2: fossil_electricity | AM2: fossil_energy_per_capita | AN2: fossil_fuel_consumption | AO2: fossil_share_elec | AP2: fossil_share_energy | AQ2: gas_cons_change_pct | AR2: gas_cons_change_twh | AS2: gas_consumption | AT2: gas_elec_per_capita | AU2: gas_electricity | AV2: gas_energy_per_capita | AW2: gas_prod_change_pct | AX2: gas_prod_change_twh | AY2: gas_prod_per_capita | AZ2: gas_production | BA2: gas_share_elec | BB2: gas_share_energy | BC2: greenhouse_gas_emissions | BD2: hydro_cons_change_pct | BE2: hydro_cons_change_twh | BF2: hydro_consumption | BG2: hydro_elec_per_capita | BH2: hydro_electricity | BI2: hydro_energy_per_capita | BJ2: hydro_share_elec | BK2: hydro_share_energy | BL2: low_carbon_cons_change_pct | BM2: low_carbon_cons_change_twh | BN2: low_carbon_consumption | BO2: low_carbon_elec_per_capita | BP2: low_carbon_electricity | BQ2: low_carbon_energy_per_capita | BR2: low_carbon_share_elec | BS2: low_carbon_share_energy | BT2: net_elec_imports | BU2: net_elec_imports_share_demand | BV2: nuclear_cons_change_pct | BW2: nuclear_cons_change_twh | BX2: nuclear_consumption | BY2: nuclear_elec_per_capita | BZ2: nuclear_electricity | CA2: nuclear_energy_per_capita | CB2: nuclear_share_elec | CC2: nuclear_share_energy | CD2: oil_cons_change_pct | CE2: oil_cons_change_twh | CF2: oil_consumption | CG2: oil_elec_per_capita | CH2: oil_electricity | CI2: oil_energy_per_capita | CJ2: oil_prod_change_pct | CK2: oil_prod_change_twh | CL2: oil_prod_per_capita | CM2: oil_production | CN2: oil_share_elec | CO2: oil_share_energy | CP2: other_renewable_consumption | CQ2: other_renewable_electricity | CR2: other_renewable_exc_biofuel_electricity | CS2: other_renewables_cons_change_pct | CT2: other_renewables_cons_change_twh | CU2: other_renewables_elec_per_capita | CV2: other_renewables_elec_per_capita_exc_biofuel | CW2: other_renewables_energy_per_capita | CX2: other_renewables_share_elec | CY2: other_renewables_share_elec_exc_biofuel | CZ2: other_renewables_share_energy | DA2: per_capita_electricity | DB2: primary_energy_consumption | DC2: renewables_cons_change_pct | DD2: renewables_cons_change_twh | DE2: renewables_consumption | DF2: renewables_elec_per_capita | DG2: renewables_electricity | DH2: renewables_energy_per_capita | DI2: renewables_share_elec | DJ2: renewables_share_energy | DK2: solar_cons_change_pct | DL2: solar_cons_change_twh | DM2: solar_consumption | DN2: solar_elec_per_capita | DO2: solar_electricity | DP2: solar_energy_per_capita | DQ2: solar_share_elec | DR2: solar_share_energy | DS2: wind_cons_change_pct | DT2: wind_cons_change_twh | DU2: wind_consumption | DV2: wind_elec_per_capita | DW2: wind_electricity | DX2: wind_energy_per_capita | DY2: wind_share_elec | DZ2: wind_share_energy
A3: Indonesia | B3: 2016 | C3: IDN | D3: 264627429 | E3: 2819889903036 | F3: 228.74318 | G3: 19.137562 | H3: 103.93465 | I3: 27.50396 | J3: 39 | K3: 10.21 | L3: 3.9642789 | M3: 1.4575197 | N3: 689.03003 | O3: 2.262413 | P3: 12.042236 | Q3: 2056.9153 | R3: 544.31622 | S3: 511.58719 | T3: 135.38 | U3: -3.0970335 | V3: -87.644531 | W3: 10362.896 | X3: 2742.3064 | Y3: 52.564556 | Z3: 28.844994 | AA3: 258.23999 | AB3: 975.86255 | AC3: 257.54999 | AD3: 13.963207 | AE3: -0.64502597 | AF3: -12.232666 | AG3: 7120.3066 | AH3: 0.66819221 | AI3: -2.5331471 | AJ3: -46.194489 | AK3: 823.68634 | AL3: 217.97 | AM3: 6716.6367 | AN3: 1777.4062 | AO3: 84.632118 | AP3: 94.190239 | AQ3: -6.1996994 | AR3: -29.090851 | AS3: 440.13916 | AT3: 233 | AU3: 61.790001 | AV3: 1663.2408 | AW3: -1.5809186 | AX3: -13.698303 | AY3: 3222.5654 | AZ3: 852.77917 | BA3: 23.991459 | BB3: 23.324331 | BC3: 177.46001 | BD3: 35.925537 | BE3: 12.140705 | BF3: 46.926857 | BG3: 70.589813 | BH3: 18.68 | BI3: 177.3318 | BJ3: 7.2529612 | BK3: 2.4867988 | BL3: 76.044907 | BM3: 33.587925 | BN3: 109.63251 | BO3: 149.56879 | BP3: 39.580002 | BQ3: 414.29004 | BR3: 15.367891 | BS3: 5.8097644 | BT3: 0.69 | BU3: 0.26719332 | BW3: 0 | BX3: 0 | BY3: 0 | BZ3: 0 | CA3: 0 | CB3: 0 | CC3: 0 | CD3: -3.5453095 | CE3: -29.145874 | CF3: 792.95087 | CG3: 78.601074 | CH3: 20.799999 | CI3: 2996.4802 | CJ3: 5.0993538 | CK3: 24.065979 | CL3: 1874.3624 | CM3: 496.00772 | CN3: 8.0761023 | CO3: 42.020912 | CP3: 35.134403 | CQ3: 20.869999 | CR3: 10.66 | CS3: 6.8912568 | CT3: 2.2651062 | CU3: 79 | CV3: 40 | CW3: 132.76932 | CX3: 8.103281 | CY3: 4.1390023 | CZ3: 1.8618803 | DA3: 973.25507 | DB3: 1884.2284 | DC3: 76.044907 | DD3: 33.587925 | DE3: 109.63251 | DF3: 149.56879 | DG3: 39.580002 | DH3: 414.29004 | DI3: 15.367891 | DJ3: 5.8097644 | DK3: 299.43182 | DL3: 0.039622866 | DM3: 0.052989952 | DN3: 0.075577952 | DO3: 0.02 | DP3: 0.20024361 | DQ3: 0.0077654826 | DR3: 0.002808101 | DS3: 53.783783 | DT3: 0.0049293935 | DU3: 0.014296482 | DV3: 0 | DW3: 0.0099999998 | DX3: 0.054024946 | DY3: 0.0038827413 | DZ3: 0.00075761467
A4: Indonesia | B4: 2017 | C4: IDN | D4: 267346654 | E4: 2962852274581 | F4: -14.494685 | G4: -3.9866123 | H4: 87.965744 | I4: 23.517347 | J4: 43 | K4: 11.47 | L4: 4.3147879 | M4: 1.1596593 | N4: 688.48999 | O4: 4.0037107 | P4: 21.792847 | Q4: 2117.5095 | R4: 566.10907 | S4: 553.43878 | T4: 147.96001 | U4: -1.8675206 | V4: -51.213135 | W4: 10065.932 | X4: 2691.0933 | Y4: 55.659637 | Z4: 27.915293 | AA4: 266.95001 | AB4: 998.51636 | AC4: 265.82999 | AD4: 13.407044 | AE4: 7.4026604 | AF4: 139.48303 | AG4: 7569.6157 | AH4: 0.6830281 | AI4: 7.8006887 | AJ4: 138.64993 | AK4: 832.77643 | AL4: 222.64 | AM4: 7166.9355 | AN4: 1916.0562 | AO4: 83.752777 | AP4: 94.482269 | AQ4: 13.512967 | AR4: 59.475861 | AS4: 499.61502 | AT4: 209 | AU4: 55.830002 | AV4: 1868.791 | AW4: -2.4478142 | AX4: -20.874451 | AY4: 3111.708 | AZ4: 831.90472 | BA4: 21.002146 | BB4: 24.636417 | BC4: 183.02 | BD4: -0.23826425 | BE4: -0.34588623 | BF4: 46.580971 | BG4: 69.684807 | BH4: 18.629999 | BI4: 174.23434 | BJ4: 7.0082383 | BK4: 2.2969451 | BL4: -3.3411674 | BM4: 2.2644691 | BN4: 111.89697 | BO4: 161.55055 | BP4: 43.189999 | BQ4: 418.54639 | BR4: 16.247227 | BS4: 5.5177298 | BT4: 1.12 | BU4: 0.4195542 | BW4: 0 | BX4: 0 | BY4: 0 | BZ4: 0 | CA4: 0 | CB4: 0 | CC4: 0 | CD4: 7.2364163 | CE4: 57.381226 | CF4: 850.33209 | CG4: 70.507713 | CH4: 18.85 | CI4: 3180.6348 | CJ4: -3.990025 | CK4: -19.790833 | CL4: 1781.2711 | CM4: 476.21689 | CN4: 7.0909986 | CO4: 41.930557 | CP4: 41.726032 | CQ4: 24.530001 | CR4: 13.06 | CS4: 18.761175 | CT4: 6.591629 | CU4: 92 | CV4: 49 | CW4: 156.07463 | CX4: 9.2277031 | CY4: 4.9129148 | CZ4: 2.0575442 | DA4: 994.32697 | DB4: 2023.7114 | DC4: -3.3411674 | DD4: 2.2644691 | DE4: 111.89697 | DF4: 161.55055 | DG4: 43.189999 | DH4: 418.54639 | DI4: 16.247227 | DJ4: 5.5177298 | DK4: 37.743 | DL4: 0.019635044 | DM4: 0.072624996 | DN4: 0.11221386 | DO4: 0.029999999 | DP4: 0.27165103 | DQ4: 0.011285408 | DR4: 0.003581197 | DS4: -100 | DT4: -0.014296482 | DU4: 0 | DV4: 0 | DW4: 0 | DX4: 0 | DY4: 0 | DZ4: 0
A5: Indonesia | B5: 2018 | C5: IDN | D5: 269951847 | E5: 3116158974437 | F5: 45.800938 | G5: 10.771166 | H5: 127.01714 | I5: 34.288513 | J5: 45 | K5: 12.13 | L5: 4.2742872 | M5: 1.6056603 | N5: 684.06 | O5: 15.830925 | P5: 89.6203 | Q5: 2429.0605 | R5: 655.72937 | S5: 592.73529 | T5: 160.00999 | U5: 18.100971 | V5: 487.11401 | W5: 11773.237 | X5: 3178.2073 | Y5: 56.383236 | Z5: 30.706453 | AA5: 285.29001 | AB5: 1056.8181 | AC5: 283.79001 | AD5: 13.86582 | AE5: 5.3293343 | AF5: 107.85034 | AG5: 7896.0815 | AH5: 0.684035 | AI5: 2.5032041 | AJ5: 47.962799 | AK5: 872.04443 | AL5: 235.41 | AM5: 7275.4419 | AN5: 1964.019 | AO5: 82.952179 | AP5: 91.970955 | AQ5: -13.719457 | AR5: -68.544464 | AS5: 431.07056 | AT5: 213 | AU5: 57.450001 | AV5: 1596.8424 | AW5: -0.25397053 | AX5: -2.112793 | AY5: 3073.8516 | AZ5: 829.79193 | BA5: 20.243841 | BB5: 20.186146 | BC5: 194.13 | BD5: 16.12241 | BE5: 7.2408676 | BF5: 53.821838 | BG5: 80.162445 | BH5: 21.639999 | BI5: 199.3757 | BJ5: 7.6253562 | BK5: 2.5203657 | BL5: 48.841637 | BM5: 59.561394 | BN5: 171.45837 | BO5: 179.21715 | BP5: 48.380001 | BQ5: 635.14429 | BR5: 17.047817 | BS5: 8.0290422 | BT5: 1.5 | BU5: 0.5257808 | BW5: 0 | BX5: 0 | BY5: 0 | BZ5: 0 | CA5: 0 | CB5: 0 | CC5: 0 | CD5: 3.1619368 | CE5: 26.886963 | CF5: 877.21906 | CG5: 66.49334 | CH5: 17.950001 | CI5: 3249.5391 | CJ5: -3.6407616 | CK5: -17.337921 | CL5: 1699.8549 | CM5: 458.87897 | CN5: 6.3250995 | CO5: 41.078358 | CP5: 82.650879 | CQ5: 26.459999 | CR5: 14.33 | CS5: 98.079887 | CT5: 40.924847 | CU5: 98 | CV5: 53 | CW5: 306.16898 | CX5: 9.3237953 | CY5: 5.0495081 | CZ5: 3.8703701 | DA5: 1051.2616 | DB5: 2131.5618 | DC5: 48.841637 | DD5: 59.561394 | DE5: 171.45837 | DF5: 179.21715 | DG5: 48.380001 | DH5: 635.14429 | DI5: 17.047817 | DJ5: 8.0290422 | DK5: 210.7401 | DL5: 0.15192723 | DM5: 0.22455223 | DN5: 0.3333928 | DO5: 0.090000004 | DP5: 0.83182329 | DQ5: 0.03171359 | DR5: 0.010515317 | DT5: 0.47258705 | DU5: 0.47258705 | DV5: 1 | DW5: 0.19 | DX5: 1.7506347 | DY5: 0.06695091 | DZ5: 0.022130277
A6: Indonesia | B6: 2019 | C6: IDN | D6: 272489381 | E6: 3272568062078 | F6: 70.559998 | G6: 24.193974 | H6: 214.623 | I6: 58.482487 | J6: 45 | K6: 12.17 | L6: 4.1192799 | M6: 2.5899904 | N6: 693.81 | O6: 22.189302 | P6: 145.50177 | Q6: 2940.4124 | R6: 801.23114 | S6: 640.35522 | T6: 174.49001 | U6: 12.221391 | V6: 388.42114 | W6: 13089.055 | X6: 3566.6284 | Y6: 59.061062 | Z6: 35.483803 | AA6: 297.12 | AB6: 1090.3911 | AC6: 295.44 | AD6: 13.614369 | AE6: 5.7411985 | AF6: 122.3772 | AG6: 8271.6582 | AH6: 0.68873709 | AI6: 5.0670948 | AJ6: 99.518707 | AK6: 907.92529 | AL6: 247.39999 | AM6: 7572.9106 | AN6: 2063.5376 | AO6: 83.739502 | AP6: 91.38707 | AQ6: -5.5366039 | AR6: -23.866669 | AS6: 407.20389 | AT6: 229 | AU6: 62.32 | AV6: 1494.3844 | AW6: -8.9233189 | AX6: -74.044983 | AY6: 2773.4915 | AZ6: 755.74695 | BA6: 21.093962 | BB6: 18.033676 | BC6: 204.98 | BD6: -2.1971326 | BE6: -1.4431305 | BF6: 52.378708 | BG6: 77.654404 | BH6: 21.16 | BI6: 192.22293 | BJ6: 7.1621985 | BK6: 2.319675 | BL6: 28.884277 | BM6: 23.023302 | BN6: 194.48167 | BO6: 176.30045 | BP6: 48.040001 | BQ6: 713.72205 | BR6: 16.260492 | BS6: 8.6129322 | BT6: 1.6799999 | BU6: 0.56542808 | BW6: 0 | BX6: 0 | BY6: 0 | BZ6: 0 | CA6: 0 | CB6: 0 | CC6: 0 | CD6: -2.521194 | CE6: -22.116394 | CF6: 855.10266 | CG6: 38.863899 | CH6: 10.59 | CI6: 3138.1138 | CJ6: -3.3770988 | CK6: -15.496796 | CL6: 1627.1539 | CM6: 443.38217 | CN6: 3.5844841 | CO6: 37.869591 | CP6: 82.129684 | CQ6: 26.279999 | CR6: 14.11 | CS6: -0.63059098 | CT6: -0.52119446 | CU6: 96 | CV6: 52 | CW6: 301.40509 | CX6: 8.8952074 | CY6: 4.7759271 | CZ6: 3.6372445 | DA6: 1084.2257 | DB6: 2253.939 | DC6: 28.884277 | DD6: 23.023302 | DE6: 194.48167 | DF6: 176.30045 | DG6: 48.040001 | DH6: 713.72205 | DI6: 16.260492 | DJ6: 8.6129322 | DK6: 31.029139 | DL6: 0.068220034 | DM6: 0.29277226 | DN6: 0.44038412 | DO6: 0.12 | DP6: 1.0744355 | DQ6: 0.040617384 | DR6: 0.012965888 | DS6: 154.76366 | DT6: 0.72543269 | DU6: 1.1980197 | DV6: 2 | DW6: 0.47999999 | DX6: 4.396574 | DY6: 0.16246954 | DZ6: 0.053056221
A7: Indonesia | B7: 2020 | C7: IDN | D7: 274814861 | E7: 3204972631957 | F7: 31.332094 | G7: 18.323788 | H7: 279.4837 | I7: 76.806274 | J7: 45 | K7: 12.35 | L7: 4.2320609 | M7: 3.6212845 | N7: 685.15002 | O7: -4.4745212 | P7: -35.851257 | Q7: 2785.0745 | R7: 765.37988 | S7: 658.15216 | T7: 180.87 | U7: -8.2749023 | V7: -295.13501 | W7: 11904.354 | X7: 3271.4934 | Y7: 61.979984 | Z7: 36.086353 | AA7: 293.37 | AB7: 1067.5187 | AC7: 291.82001 | AD7: 14.411448 | AE7: -6.1061397 | AF7: -137.62866 | AG7: 7700.8584 | AH7: 0.66032088 | AI7: -8.1566648 | AJ7: -168.31586 | AK7: 869.42163 | AL7: 238.92999 | AM7: 6896.3584 | AN7: 1895.2218 | AO7: 81.875809 | AP7: 89.356468 | AQ7: -7.508182 | AR7: -30.573608 | AS7: 376.63028 | AT7: 187 | AU7: 51.279999 | AV7: 1370.4873 | AW7: -12.08845 | AX7: -91.358093 | AY7: 2417.5872 | AZ7: 664.38885 | BA7: 17.572475 | BB7: 17.757475 | BC7: 199.94 | BD7: 14.952042 | BE7: 7.6830215 | BF7: 60.061729 | BG7: 88.532333 | BH7: 24.33 | BI7: 218.55342 | BJ7: 8.3373308 | BK7: 2.8318079 | BL7: 21.760138 | BM7: 31.264135 | BN7: 225.7458 | BO7: 192.45683 | BP7: 52.889999 | BQ7: 821.44684 | BR7: 18.124186 | BS7: 10.643529 | BT7: 1.55 | BU7: 0.52834302 | BW7: 0 | BX7: 0 | BY7: 0 | BZ7: 0 | CA7: 0 | CB7: 0 | CC7: 0 | CD7: -11.915645 | CE7: -101.89099 | CF7: 753.21167 | CG7: 24.671156 | CH7: 6.7800002 | CI7: 2740.7966 | CJ7: -4.6942658 | CK7: -20.813538 | CL7: 1537.6484 | CM7: 422.56863 | CN7: 2.32335 | CO7: 35.512642 | CP7: 87.282814 | CQ7: 27.92 | CR7: 15.57 | CS7: 6.2743764 | CT7: 5.1531296 | CU7: 102 | CV7: 57 | CW7: 317.60587 | CX7: 9.5675411 | CY7: 5.3354807 | CZ7: 4.1152353 | DA7: 1061.8785 | DB7: 2116.3103 | DC7: 21.760138 | DD7: 31.264135 | DE7: 225.7458 | DF7: 192.45683 | DG7: 52.889999 | DH7: 821.44684 | DI7: 18.124186 | DJ7: 10.643529 | DK7: 44.546829 | DL7: 0.12937587 | DM7: 0.42214814 | DN7: 0.61859828 | DO7: 0.17 | DP7: 1.5361183 | DQ7: 0.058255088 | DR7: 0.019903563 | DS7: -1.8595048 | DT7: -0.025180221 | DU7: 1.1728395 | DV7: 2 | DW7: 0.47 | DX7: 4.2677441 | DY7: 0.16105819 | DZ7: 0.055297378
A8: Indonesia | B8: 2021 | C8: IDN | D8: 276758056 | E8: 3323654666991 | F8: 10.642851 | G8: 8.1743774 | H8: 307.05756 | I8: 84.980652 | J8: 54 | K8: 14.96 | L8: 4.8357902 | M8: 3.8600438 | N8: 684.40997 | O8: -0.28094134 | P8: -2.1502686 | Q8: 2757.7502 | R8: 763.22961 | S8: 686.37573 | T8: 189.96001 | U8: 7.6657176 | V8: 250.78345 | W8: 12726.917 | X8: 3522.2769 | Y8: 61.404194 | Z8: 34.667889 | AA8: 310.32999 | AB8: 1121.3042 | AC8: 309.35999 | AD8: 14.73927 | AE8: 3.7976644 | AF8: 80.370361 | AG8: 7937.188 | AH8: 0.66092324 | AI8: 3.2967188 | AJ8: 62.480133 | AK8: 914.73401 | AL8: 253.16 | AM8: 7073.6948 | AN8: 1957.7019 | AO8: 81.833466 | AP8: 88.92395 | AQ8: 8.2649555 | AR8: 31.128326 | AS8: 407.75861 | AT8: 204 | AU8: 56.529999 | AV8: 1473.3396 | AW8: 0.1632286 | AX8: 1.0844727 | AY8: 2404.531 | AZ8: 665.47333 | BA8: 18.273211 | BB8: 18.521463 | BC8: 211.73 | BD8: 1.5292897 | BE8: 0.76832199 | BF8: 60.830051 | BG8: 89.247627 | BH8: 24.700001 | BI8: 219.79506 | BJ8: 7.9842262 | BK8: 2.7630603 | BL8: 8.8460617 | BM8: 18.098497 | BN8: 243.8443 | BO8: 203.06546 | BP8: 56.200001 | BQ8: 881.07391 | BR8: 18.166538 | BS8: 11.076047 | BT8: 0.97000003 | BU8: 0.31257051 | BW8: 0 | BX8: 0 | BY8: 0 | BZ8: 0 | CA8: 0 | CB8: 0 | CC8: 0 | CD8: 4.4478965 | CE8: 33.502075 | CF8: 786.71375 | CG8: 24.100473 | CH8: 6.6700001 | CI8: 2842.6047 | CJ8: -7.1710873 | CK8: -30.302765 | CL8: 1417.3602 | CM8: 392.26587 | CN8: 2.1560643 | CO8: 35.7346 | CP8: 96.482811 | CQ8: 30.869999 | CR8: 15.91 | CS8: 10.540449 | CT8: 9.1999969 | CU8: 112 | CV8: 57 | CW8: 348.61789 | CX8: 9.9786663 | CY8: 5.1428757 | CZ8: 4.3825021 | DA8: 1117.7994 | DB8: 2196.6807 | DC8: 8.8460617 | DD8: 18.098497 | DE8: 243.8443 | DF8: 203.06546 | DG8: 56.200001 | DH8: 881.07391 | DI8: 18.166538 | DJ8: 11.076047 | DK8: 12.663042 | DL8: 0.052285373 | DM8: 0.47443351 | DN8: 0.68652022 | DO8: 0.19 | DP8: 1.7142537 | DQ8: 0.061417121 | DR8: 0.021550013 | DS8: -7.9999976 | DT8: -0.09648478 | DU8: 1.0763547 | DV8: 2 | DW8: 0.44 | DX8: 3.8891542 | DY8: 0.14222912 | DZ8: 0.048890851
A9: Indonesia | B9: 2022 | C9: IDN | D9: 278830527 | E9: 3500093638879 | F9: 12.427369 | G9: 10.56086 | H9: 342.65082 | I9: 95.541512 | J9: 74 | K9: 20.620001 | L9: 6.1821671 | M9: 3.4691505 | N9: 675.81 | O9: 59.389862 | P9: 453.28101 | Q9: 4362.9033 | R9: 1216.5106 | S9: 736.32538 | T9: 205.31 | U9: 10.037883 | V9: 353.56201 | W9: 13900.339 | X9: 3875.8389 | Y9: 61.554832 | Z9: 44.171986 | AA9: 334.34 | AB9: 1199.0796 | AC9: 333.54001 | AD9: 12.663559 | AE9: 25.154396 | AF9: 552.56177 | AG9: 9859.9043 | AH9: 0.7854768 | AI9: 26.316742 | AJ9: 515.20337 | AK9: 961.62354 | AL9: 268.13 | AM9: 8868.8477 | AN9: 2472.9053 | AO9: 80.38916 | AP9: 89.792183 | AQ9: -2.3142128 | AR9: -9.4364014 | AS9: 398.3222 | AT9: 203 | AU9: 56.709999 | AV9: 1428.5459 | AW9: -1.5751095 | AX9: -10.481934 | AY9: 2349.0664 | AZ9: 654.99139 | BA9: 17.002459 | BB9: 14.463239 | BC9: 225.41 | BD9: 10.519494 | BE9: 6.2338295 | BF9: 67.063881 | BG9: 97.908936 | BH9: 27.299999 | BI9: 240.51843 | BJ9: 8.1849251 | BK9: 2.4351163 | BL9: 13.990807 | BM9: 37.28228 | BN9: 281.12659 | BO9: 234.58696 | BP9: 65.410004 | BQ9: 1008.2346 | BR9: 19.610842 | BS9: 10.207819 | BT9: 0.80000001 | BU9: 0.23927739 | BW9: 0 | BX9: 0 | BY9: 0 | BZ9: 0 | CA9: 0 | CB9: 0 | CC9: 0 | CD9: 9.070487 | CE9: 71.358765 | CF9: 858.07251 | CG9: 21.912952 | CH9: 6.1100001 | CI9: 3077.3979 | CJ9: -6.694037 | CK9: -26.258423 | CL9: 1312.652 | CM9: 366.00745 | CN9: 1.8318642 | CO9: 31.156956 | CP9: 116.55625 | CQ9: 37.310001 | CR9: 16.690001 | CS9: 20.805195 | CT9: 20.073441 | CU9: 134 | CV9: 60 | CW9: 418.01825 | CX9: 11.186065 | CY9: 5.0038977 | CZ9: 4.232204 | DA9: 1196.2106 | DB9: 2749.2424 | DC9: 13.990807 | DD9: 37.28228 | DE9: 281.12659 | DF9: 234.58696 | DG9: 65.410004 | DH9: 1008.2346 | DI9: 19.610842 | DJ9: 10.207819 | DK9: 130.36549 | DL9: 0.61581218 | DM9: 1.0902457 | DN9: 1.5780195 | DO9: 0.44 | DP9: 3.9100659 | DQ9: 0.13191821 | DR9: 0.039587259 | DS9: -18.535469 | DT9: -0.20166188 | DU9: 0.87469286 | DV9: 1 | DW9: 0.36000001 | DX9: 3.1370053 | DY9: 0.10793308 | DZ9: 0.031760447
A10: Indonesia | B10: 2023 | C10: IDN | D10: 281190068 | F10: 17.619661 | G10: 16.834091 | H10: 399.64285 | I10: 112.3756 | J10: 80 | K10: 22.48 | L10: 6.4118652 | M10: 4.0274487 | N10: 680.79999 | O10: -1.3649178 | P10: -16.60437 | Q10: 4267.2427 | R10: 1199.9062 | S10: 770.93762 | T10: 216.78 | U10: 12.764814 | V10: 494.74365 | W10: 15543.161 | X10: 4370.5825 | Y10: 61.831146 | Z10: 43.003647 | AA10: 351.48999 | AB10: 1250.0085 | AC10: 350.60001 | AD10: 13.134049 | AE10: 1.3055443 | AF10: 35.892578 | AG10: 9904.8125 | AI10: 0.76495922 | AJ10: 18.916718 | AK10: 1014.9718 | AL10: 285.39999 | AM10: 8861.7002 | AN10: 2491.822 | AO10: 81.403305 | AP10: 89.30484 | AQ10: 9.0773125 | AR10: 36.156952 | AS10: 434.47916 | AT10: 221 | AU10: 62.040001 | AV10: 1545.144 | AW10: 4.0378408 | AX10: 26.44751 | AY10: 2423.4104 | AZ10: 681.4389 | BA10: 17.695379 | BB10: 15.571374 | BC10: 238.69 | BD10: -9.9102392 | BE10: -7.0882721 | BF10: 59.975609 | BG10: 87.449745 | BH10: 24.59 | BI10: 213.29205 | BJ10: 7.0136909 | BK10: 2.1494763 | BL10: 10.336974 | BM10: 17.294321 | BN10: 298.4209 | BO10: 231.87163 | BP10: 65.199997 | BQ10: 1061.2782 | BR10: 18.596691 | BS10: 10.695158 | BT10: 0.88999999 | BU10: 0.25320777 | BW10: 0 | BX10: 0 | BY10: 0 | BZ10: 0 | CA10: 0 | CB10: 0 | CC10: 0 | CD10: -0.074103788 | CE10: -0.63586426 | CF10: 857.43665 | CG10: 23.400541 | CH10: 6.5799999 | CI10: 3049.3135 | CJ10: -1.1973487 | CK10: -4.3823853 | CL10: 1286.052 | CM10: 361.62506 | CN10: 1.8767827 | CO10: 30.72982 | CP10: 123.15781 | CQ10: 39.419998 | CR10: 16.940001 | CS10: 5.6638403 | CT10: 6.6015625 | CU10: 140 | CV10: 60 | CW10: 437.98779 | CX10: 11.243583 | CY10: 4.831717 | CZ10: 4.4138741 | DA10: 1246.8435 | DB10: 2785.135 | DC10: 10.336974 | DD10: 17.294321 | DE10: 298.4209 | DF10: 231.87163 | DG10: 65.199997 | DH10: 1061.2782 | DI10: 18.596691 | DJ10: 10.695158 | DK10: 60.654003 | DL10: 0.64846158 | DM10: 1.7387073 | DN10: 2.5249825 | DO10: 0.70999998 | DP10: 6.1833882 | DQ10: 0.20250997 | DR10: 0.062313832 | DS10: 35.112358 | DT10: 0.29847795 | DU10: 1.1731708 | DV10: 2 | DW10: 0.47999999 | DX10: 4.172163 | DY10: 0.13690816 | DZ10: 0.04204547
A11: Indonesia | B11: 2024 | C11: IDN | D11: 283487933 | F11: 7.3672094 | G11: 8.2789459 | H11: 425.60736 | I11: 120.65455 | J11: 75 | K11: 21.33 | L11: 5.7409697 | M11: 4.0343947 | N11: 680.25 | O11: 9.2873468 | P11: 111.43945 | Q11: 4625.7549 | R11: 1311.3457 | S11: 805.78381 | T11: 228.42999 | U11: 7.8624368 | V11: 343.63428 | W11: 16629.338 | X11: 4714.2168 | Y11: 61.481937 | Z11: 43.848213 | AA11: 372.5 | AB11: 1313.9889 | AC11: 371.54001 | AD11: 13.032324 | AE11: 7.1664815 | AF11: 199.59619 | AG11: 10528.601 | AI11: 6.8714671 | AJ11: 171.22473 | AK11: 1073.52 | AL11: 304.32999 | AM11: 9393.8633 | AN11: 2663.0469 | AO11: 81.910423 | AP11: 89.045807 | AQ11: 8.8008347 | AR11: 38.237793 | AS11: 472.71695 | AT11: 243 | AU11: 68.779999 | AV11: 1667.5029 | AW11: 4.7617693 | AX11: 32.448547 | AY11: 2518.2288 | AZ11: 713.88745 | BA11: 18.512138 | BB11: 15.806505 | BC11: 252.74001 | BD11: 7.7133207 | BE11: 4.6261139 | BF11: 64.601723 | BG11: 96.265121 | BH11: 27.290001 | BI11: 227.88174 | BJ11: 7.3451042 | BK11: 2.1601245 | BL11: 8.6898575 | BM11: 29.180389 | BN11: 327.60129 | BO11: 237.0824 | BP11: 67.209999 | BQ11: 1155.6093 | BR11: 18.089573 | BS11: 10.95419 | BT11: 0.95999998 | BU11: 0.25771812 | BW11: 0 | BX11: 0 | BY11: 0 | BZ11: 0 | CA11: 0 | CB11: 0 | CC11: 0 | CD11: 2.5130119 | CE11: 21.547485 | CF11: 878.98413 | CG11: 25.115707 | CH11: 7.1199999 | CI11: 3100.605 | CJ11: -3.7777655 | CK11: -13.661346 | CL11: 1227.4375 | CM11: 347.96371 | CN11: 1.9163481 | CO11: 29.391092 | CP11: 138.91292 | CQ11: 38.099998 | CR11: 16.77 | CS11: 12.792615 | CT11: 15.755104 | CU11: 134 | CV11: 59 | CW11: 490.01352 | CX11: 10.254616 | CY11: 4.5136461 | CZ11: 4.6449103 | DA11: 1310.6025 | DB11: 2984.7312 | DC11: 8.6898575 | DD11: 29.180389 | DE11: 327.60129 | DF11: 237.0824 | DG11: 67.209999 | DH11: 1155.6093 | DI11: 18.089573 | DJ11: 10.95419 | DK11: 29.73534 | DL11: 0.51701069 | DM11: 2.255718 | DN11: 4.7621074 | DO11: 1.35 | DP11: 7.957016 | DQ11: 0.36335254 | DR11: 0.075425722 | DS11: 0.27397069 | DT11: 0.0032141209 | DU11: 1.1763849 | DV11: 2 | DW11: 0.47 | DX11: 4.1496825 | DY11: 0.1265005 | DZ11: 0.039335452

Sheet province_power_capacity_2025_ra
A1: province_code | B1: province | C1: hydro_pp_mw | D1: mini_hydro_pp_mw | E1: micro_hydro_pp_mw | F1: geothermal_pp_mw | G1: solar_pp_mw | H1: wind_pp_mw | I1: biogas_pp_mw | J1: biomass_pp_mw | K1: biofuel_pp_mw | L1: waste_pp_mw | M1: diesel_pp_mw | N1: steam_pp_mw | O1: gas_pp_mw | P1: coal_gasification_pp_mw | Q1: combined_cycle_pp_mw | R1: gas_engine_pp_mw | S1: other_pp_mw | T1: total_mw
A2: 11 | B2: Aceh | C2: 10 | D2: 23.4 | E2: 4.45 | F2: 0 | G2: 1.46 | H2: 0 | I2: 0 | J2: 25.1 | K2: 0 | L2: 0 | M2: 218.94 | N2: 648 | O2: 0 | P2: 0 | Q2: 24 | R2: 430.67 | S2: 0 | T2: 1386.01
A3: 51 | B3: Bali | C3: 0 | D3: 2.5 | E3: 0.03 | F3: 0 | G3: 41.6 | H3: 1.08 | I3: 0 | J3: 0 | K3: 0 | L3: 0 | M3: 127.71 | N3: 380 | O3: 584.53 | P3: 0 | Q3: 0 | R3: 199.66 | S3: 0 | T3: 1337.11
A4: 36 | B4: Banten | C4: 0 | D4: 0 | E4: 15.5 | F4: 0 | G4: 91.53 | H4: 0 | I4: 0 | J4: 0 | K4: 0 | L4: 0 | M4: 165.53 | N4: 11436.44 | O4: 80.6 | P4: 200 | Q4: 859.4 | R4: 12.25 | S4: 18 | T4: 12879.25
A5: 17 | B5: Bengkulu | C5: 277.15 | D5: 42.77 | E5: 2.64 | F5: 0 | G5: 0.41 | H5: 0 | I5: 3.3 | J5: 15.04 | K5: 0 | L5: 0 | M5: 21.39 | N5: 200 | O5: 0 | P5: 0 | Q5: 0 | R5: 0 | S5: 0 | T5: 562.7
A6: 34 | B6: DI Yogyakarta | C6: 0 | D6: 0 | E6: 0.5 | F6: 0 | G6: 4.17 | H6: 0 | I6: 0 | J6: 3.8 | K6: 0 | L6: 0 | M6: 8.31 | N6: 0 | O6: 0 | P6: 0 | Q6: 0 | R6: 0 | S6: 0 | T6: 16.78
A7: 31 | B7: DKI Jakarta | C7: 0 | D7: 0 | E7: 0 | F7: 0 | G7: 65.33 | H7: 0 | I7: 0 | J7: 0 | K7: 0 | L7: 0 | M7: 504.12 | N7: 400 | O7: 0 | P7: 0 | Q7: 4614.07 | R7: 0 | S7: 0 | T7: 5583.52
A8: 75 | B8: Gorontalo | C8: 0 | D8: 14.9 | E8: 1.67 | F8: 0 | G8: 13.21 | H8: 0 | I8: 0 | J8: 1.94 | K8: 0 | L8: 0 | M8: 24.83 | N8: 176 | O8: 75 | P8: 0 | Q8: 0 | R8: 0 | S8: 0 | T8: 307.55
A9: 15 | B9: Jambi | C9: 492 | D9: 3.2 | E9: 1.01 | F9: 0 | G9: 1.87 | H9: 0 | I9: 6.2 | J9: 119.08 | K9: 0 | L9: 0 | M9: 19.26 | N9: 318 | O9: 100 | P9: 0 | Q9: 0 | R9: 116.92 | S9: 0 | T9: 1177.54
A10: 32 | B10: Jawa Barat | C10: 2056.6 | D10: 237.89 | E10: 4.13 | F10: 1260.68 | G10: 630.85 | H10: 0 | I10: 0 | J10: 0 | K10: 0 | L10: 14 | M10: 432.01 | N10: 4103.3 | O10: 1141.65 | P10: 0 | Q10: 4725.77 | R10: 3.48 | S10: 0 | T10: 14610.35
A11: 33 | B11: Jawa Tengah | C11: 229.8 | D11: 133.23 | E11: 9.76 | F11: 72.8 | G11: 108.61 | H11: 0 | I11: 0 | J11: 24.7 | K11: 0 | L11: 8 | M11: 96.85 | N11: 10422.4 | O11: 55 | P11: 0 | Q11: 1879.65 | R11: 0 | S11: 0 | T11: 13040.8
A12: 35 | B12: Jawa Timur | C12: 241.67 | D12: 55.55 | E12: 9.74 | F12: 34 | G12: 177.12 | H12: 0 | I12: 2.05 | J12: 178.64 | K12: 0 | L12: 13.65 | M12: 209.37 | N12: 6965.64 | O12: 176.43 | P12: 0 | Q12: 2837.36 | R12: 47.55 | S12: 0 | T12: 10948.77
A13: 61 | B13: Kalimantan Barat | C13: 0 | D13: 1.32 | E13: 5.28 | F13: 0 | G13: 7.39 | H13: 0 | I13: 10.22 | J13: 146.16 | K13: 0 | L13: 0 | M13: 323.45 | N13: 417 | O13: 34 | P13: 0 | Q13: 0 | R13: 0 | S13: 0 | T13: 944.83
... A39: 12 | B39: Sumatera Utara | C39: 1195.55 | D39: 18.5 | E39: 183.98 | F39: 710.54 | G39: 17.34 | H39: 0 | I39: 23.27 | J39: 374.91 | K39: 0 | L39: 0 | M39: 190.44 | N39: 1349 | O39: 219.26 | P39: 0 | Q39: 817.88 | R39: 34.5 | S39: 0 | T39: 5135.16

Sheet province_geothermal_reserves_20
A1: province_code | B1: province | C1: resource_speculative_mw | D1: resource_hypothetical_mw | E1: resource_possible_mw | F1: reserve_probable_mw | G1: reserve_proven_mw | H1: total_mw
A2: 11 | B2: Aceh | C2: 324 | D2: 159 | E2: 523 | F2: 25 | G2: 0 | H2: 1031
A3: 51 | B3: Bali | C3: 70 | D3: 21 | E3: 104 | F3: 110 | G3: 30 | H3: 335
A4: 36 | B4: Banten | C4: 34 | D4: 161 | E4: 323 | F4: 0 | G4: 0 | H4: 518
A5: 17 | B5: Bengkulu | C5: 134 | D5: 0 | E5: 355 | F5: 149 | G5: 200 | H5: 838
A6: 34 | B6: DI Yogyakarta | C6: 0 | D6: 0 | E6: 10 | F6: 0 | G6: 0 | H6: 10
A7: 75 | B7: Gorontalo | C7: 129 | D7: 11 | E7: 20 | F7: 0 | G7: 0 | H7: 160
A8: 15 | B8: Jambi | C8: 352 | D8: 87 | E8: 295 | F8: 35 | G8: 10 | H8: 779
A9: 32 | B9: Jawa Barat | C9: 720 | D9: 526 | E9: 1609 | F9: 110 | G9: 1455 | H9: 4420
A10: 33 | B10: Jawa Tengah | C10: 141 | D10: 271 | E10: 524 | F10: 130 | G10: 275 | H10: 1341
A11: 35 | B11: Jawa Timur | C11: 70 | D11: 365 | E11: 770 | F11: 59 | G11: 35 | H11: 1299
A12: 61 | B12: Kalimantan Barat | C12: 65 | D12: 0 | E12: 0 | F12: 0 | G12: 0 | H12: 65
A13: 63 | B13: Kalimantan Selatan | C13: 49 | D13: 1 | E13: 0 | F13: 0 | G13: 0 | H13: 50
... A33: 12 | B33: Sumatera Utara | C33: 225 | D33: 388 | E33: 613 | F33: 39 | G33: 601 | H33: 1866

Sheet province_coal_reserves_2025_raw
A1: province_code | B1: province | C1: exploration_target_mt | D1: total_inventory_mt | E1: resource_inferred_mt | F1: resource_indicated_mt | G1: resource_measured_mt | H1: resource_total_mt | I1: reserve_total_mt
A2: 11 | B2: Aceh | C2: 1.16 | D2: 20.92 | E2: 314.58 | F2: 401.94 | G2: 326.23 | H2: 1042.75 | I2: 507.05
A3: 36 | B3: Banten | C3: 5.47 | D3: 52.2 | E3: 0 | F3: 0 | G3: 0 | H3: 0 | I3: 0
A4: 17 | B4: Bengkulu | C4: 44.28 | D4: 211.92 | E4: 95.95 | F4: 88.02 | G4: 162.28 | H4: 346.24 | I4: 149.47
A5: 15 | B5: Jambi | C5: 142.37 | D5: 1145.56 | E5: 962.64 | F5: 1203.29 | G5: 1512.7 | H5: 3678.63 | I5: 1272.53
A6: 33 | B6: Jawa Tengah | C6: 0 | D6: 0.82 | E6: 0 | F6: 0 | G6: 0 | H6: 0 | I6: 0
A7: 35 | B7: Jawa Timur | C7: 0 | D7: 0.08 | E7: 0 | F7: 0 | G7: 0 | H7: 0 | I7: 0
A8: 63 | B8: Kalimantan Selatan | C8: 7.83 | D8: 1710.81 | E8: 3365.2 | F8: 2913.94 | G8: 6598.31 | H8: 12877.45 | I8: 3292.63
A9: 62 | B9: Kalimantan Tengah | C9: 37 | D9: 2803.04 | E9: 3145.04 | F9: 2919.29 | G9: 3300.58 | H9: 9364.91 | I9: 2959.9
A10: 64 | B10: Kalimantan Timur | C10: 890.55 | D10: 13901.22 | E10: 9727.17 | F10: 14876.76 | G10: 21325.71 | H10: 45929.64 | I10: 15688.57
A11: 65 | B11: Kalimantan Utara | C11: 25.79 | D11: 386.04 | E11: 892.49 | F11: 929.81 | G11: 1018.39 | H11: 2840.69 | I11: 1092.39
A12: 18 | B12: Lampung | C12: 0 | D12: 106.95 | E12: 60.32 | F12: 24.28 | G12: 10.25 | H12: 94.85 | I12: 56
A13: 82 | B13: Maluku Utara | C13: 8.22 | D13: 0 | E13: 0 | F13: 0 | G13: 0 | H13: 0 | I13: 0
... A27: 61 | B27: West Kalimantan | C27: 2.26 | D27: 463.44 | E27: 19.28 | F27: 13.15 | G27: 38.55 | H27: 70.98 | I27: 11.22

Sheet pivot and cleaned data
B3: Sum of pdrb_per_kapita | C3: Column Labels
A4: province_code | B4: Provinsi | C4: 2016 | D4: 2017 | E4: 2018 | F4: 2019 | G4: 2020 | H4: 2021 | I4: 2022 | J4: 2023 | K4: 2024 | L4: 2025 | M4: Grand Total
A5: =IFERROR(INDEX(province_power_capacity_2025_ra!$A$2:$A$38,MATCH(B5, province_power_capacity_2025_raw[province],0)),"Data Tidak Ditemukan") -> 11 | B5: ACEH | C5: 26851.88 | D5: 28096.71 | E5: 29521.25 | F5: 30879.06 | G5: 31633.38 | H5: 34673.56 | I5: 38767.08 | J5: 41407.6 | K5: 43782.22 | L5: 45770.4 | M5: 351383.14 | O5: =PROPER(B5) -> Aceh
A6: =IFERROR(INDEX(province_power_capacity_2025_ra!$A$2:$A$38,MATCH(B6, province_power_capacity_2025_raw[province],0)),"Data Tidak Ditemukan") -> 51 | B6: BALI | C6: 46211.04 | D6: 50167.07 | E6: 54433.46 | F6: 57755.96 | G6: 52015.45 | H6: 50758.32 | I6: 56092.96 | J6: 62299.21 | K6: 67318.28 | L6: 72658.49 | M6: 569710.24 | O6: =PROPER(B6) -> Bali
A7: =IFERROR(INDEX(province_power_capacity_2025_ra!$A$2:$A$38,MATCH(B7, province_power_capacity_2025_raw[province],0)),"Data Tidak Ditemukan") -> 36 | B7: BANTEN | C7: 42439.73 | D7: 45275.58 | E7: 48370.15 | F7: 52013.99 | G7: 52729.4 | H7: 55383.29 | I7: 61413.54 | J7: 66147.2 | K7: 70275.82 | L7: 74672.68 | M7: 568721.38 | O7: =PROPER(B7) -> Banten
A8: =IFERROR(INDEX(province_power_capacity_2025_ra!$A$2:$A$38,MATCH(B8, province_power_capacity_2025_raw[province],0)),"Data Tidak Ditemukan") -> 17 | B8: BENGKULU | C8: 29076.22 | D8: 31359.48 | E8: 33822.13 | F8: 36565.29 | G8: 36552.5 | H8: 39167.13 | I8: 43756.98 | J8: 46300.51 | K8: 49233.12 | L8: 52304.54 | M8: 398137.9 | O8: =PROPER(B8) -> Bengkulu
A9: =IFERROR(INDEX(province_power_capacity_2025_ra!$A$2:$A$38,MATCH(B9, province_power_capacity_2025_raw[province],0)),"Data Tidak Ditemukan") -> 34 | B9: DI YOGYAKARTA | C9: 29552.53 | D9: 31664.92 | E9: 34136.93 | F9: 36459.73 | G9: 37693.64 | H9: 40516 | I9: 44638.79 | J9: 48373.32 | K9: 51486.05 | L9: 55039.3 | M9: 409561.21 | O9: DI Yogyakarta
A10: =IFERROR(INDEX(province_power_capacity_2025_ra!$A$2:$A$38,MATCH(B10, province_power_capacity_2025_raw[province],0)),"Data Tidak Ditemukan") -> 31 | B10: DKI JAKARTA | C10: 210075.09 | D10: 228002.73 | E10: 247678.49 | F10: 268052.25 | G10: 262615.17 | H10: 274659.62 | I10: 299674.73 | J10: 322650.58 | K10: 344382.53 | L10: 367687.07 | M10: 2825478.3 | O10: DKI Jakarta
A11: =IFERROR(INDEX(province_power_capacity_2025_ra!$A$2:$A$38,MATCH(B11, province_power_capacity_2025_raw[province],0)),"Data Tidak Ditemukan") -> 75 | B11: GORONTALO | C11: 27544.77 | D11: 29565.12 | E11: 31827.62 | F11: 34976.65 | G11: 35693.26 | H11: 37086.76 | I11: 39690.94 | J11: 42340.5 | K11: 44437.14 | L11: 47476.82 | M11: 370639.58 | O11: =PROPER(B11) -> Gorontalo
A12: =IFERROR(INDEX(province_power_capacity_2025_ra!$A$2:$A$38,MATCH(B12, province_power_capacity_2025_raw[province],0)),"Data Tidak Ditemukan") -> 15 | B12: JAMBI | C12: 49494.98 | D12: 53993.4 | E12: 58224.89 | F12: 60828.86 | G12: 57957.73 | H12: 64770.93 | I12: 76224.16 | J12: 79873.36 | K12: 86774.89 | L12: 92786.06 | M12: 680929.26 | O12: =PROPER(B12) -> Jambi
A13: =IFERROR(INDEX(province_power_capacity_2025_ra!$A$2:$A$38,MATCH(B13, province_power_capacity_2025_raw[province],0)),"Data Tidak Ditemukan") -> 32 | B13: JAWA BARAT | C13: 34893.62 | D13: 37223.11 | E13: 40272.64 | F13: 43309.19 | G13: 43236.51 | H13: 45234.18 | I13: 49136.9 | J13: 52651.05 | K13: 56081.86 | L13: 59864.61 | M13: 461903.67 | O13: =PROPER(B13) -> Jawa Barat
A14: =IFERROR(INDEX(province_power_capacity_2025_ra!$A$2:$A$38,MATCH(B14, province_power_capacity_2025_raw[province],0)),"Data Tidak Ditemukan") -> 33 | B14: JAWA TENGAH | C14: 31961.95 | D14: 34234.31 | E14: 36770.96 | F14: 39388.15 | G14: 36964.78 | H14: 38568.08 | I14: 41934.46 | J14: 45162.08 | K14: 47970.48 | L14: 50823.64 | M14: 403778.89 | O14: =PROPER(B14) -> Jawa Tengah
A15: =IFERROR(INDEX(province_power_capacity_2025_ra!$A$2:$A$38,MATCH(B15, province_power_capacity_2025_raw[province],0)),"Data Tidak Ditemukan") -> 35 | B15: JAWA TIMUR | C15: 47491.52 | D15: 51228.45 | E15: 55410.61 | F15: 59015.17 | G15: 56640.82 | H15: 59988.44 | I15: 66248.49 | J15: 71121.93 | K15: 75770.26 | L15: 80855.92 | M15: 623771.61 | O15: =PROPER(B15) -> Jawa Timur
A16: =IFERROR(INDEX(province_power_capacity_2025_ra!$A$2:$A$38,MATCH(B16, province_power_capacity_2025_raw[province],0)),"Data Tidak Ditemukan") -> 61 | B16: KALIMANTAN BARAT | C16: 33190.65 | D16: 35984.53 | E16: 38814.73 | F16: 42045.41 | G16: 39622.24 | H16: 42252.66 | I16: 46092.06 | J16: 48808.92 | K16: 52702.7 | L16: 56983.66 | M16: 436497.56 | O16: =PROPER(B16) -> Kalimantan Barat
A17: =IFERROR(INDEX(province_power_capacity_2025_ra!$A$2:$A$38,MATCH(B17, province_power_capacity_2025_raw[province],0)),"Data Tidak Ditemukan") -> 63 | B17: KALIMANTAN SELATAN | C17: 36022.98 | D17: 38619.54 | E17: 41046.28 | F17: 42823.56 | G17: 44100.79 | H17: 48065.95 | I17: 60213.03 | J17: 63754.33 | K17: 67122.21 | L17: 70576.83 | M17: 512345.5 | O17: =PROPER(B17) -> Kalimantan Selatan
A18: =IFERROR(INDEX(province_power_capacity_2025_ra!$A$2:$A$38,MATCH(B18, province_power_capacity_2025_raw[province],0)),"Data Tidak Ditemukan") -> 62 | B18: KALIMANTAN TENGAH | C18: 43905.33 | D18: 48293.22 | E18: 52107.23 | F18: 56625.38 | G18: 57145.08 | H18: 62833.77 | I18: 72973.14 | J18: 75271.23 | K18: 79319.73 | L18: 84729.84 | M18: 633203.95 | O18: =PROPER(B18) -> Kalimantan Tengah
A19: =IFERROR(INDEX(province_power_capacity_2025_ra!$A$2:$A$38,MATCH(B19, province_power_capacity_2025_raw[province],0)),"Data Tidak Ditemukan") -> 64 | B19: KALIMANTAN TIMUR | C19: 145343.19 | D19: 165546.62 | E19: 174164.82 | F19: 180259.1 | G19: 161798.85 | H19: 183157.52 | I19: 238916.99 | J19: 215804.04 | K19: 212116.62 | L19: 208330.9 | M19: 1885438.6 | O19: =PROPER(B19) -> Kalimantan Timur
A20: =IFERROR(INDEX(province_power_capacity_2025_ra!$A$2:$A$38,MATCH(B20, province_power_capacity_2025_raw[province],0)),"Data Tidak Ditemukan") -> 65 | B20: KALIMANTAN UTARA | C20: 99112.33 | D20: 111318.54 | E20: 119413.88 | F20: 138751.01 | G20: 143533.29 | H20: 157091.68 | I20: 192588.32 | J20: 201788.63 | K20: 198676.76 | L20: 208210.06 | M20: 1570484.5 | O20: =PROPER(B20) -> Kalimantan Utara
A21: =IFERROR(INDEX(province_power_capacity_2025_ra!$A$2:$A$38,MATCH(B21, province_power_capacity_2025_raw[province],0)),"Data Tidak Ditemukan") -> 19 | B21: KEPULAUAN BANGKA BELITUNG | C21: 46402.47 | D21: 48827.25 | E21: 50081.95 | F21: 52232.8 | G21: 52023.4 | H21: 58406.07 | I21: 63865.51 | J21: 67812.94 | K21: 70193.32 | L21: 75322.53 | M21: 585168.24 | O21: =PROPER(B21) -> Kepulauan Bangka Belitung
A22: =IFERROR(INDEX(province_power_capacity_2025_ra!$A$2:$A$38,MATCH(B22, province_power_capacity_2025_raw[province],0)),"Data Tidak Ditemukan") -> 21 | B22: KEPULAUAN RIAU | C22: 106503.78 | D22: 109332.85 | E22: 116461.4 | F22: 119394.66 | G22: 123464.79 | H22: 131883.84 | I22: 145530.48 | J22: 154065.16 | K22: 161424.32 | L22: 172458.76 | M22: 1340520 | O22: =PROPER(B22) -> Kepulauan Riau
... A29: =IFERROR(INDEX(province_power_capacity_2025_ra!$A$2:$A$38,MATCH(B29, province_power_capacity_2025_raw[province],0)),"Data Tidak Ditemukan") -> 92 | B29: PAPUA BARAT | C29: 74584.63 | D29: 78423.63 | E29: 84958.03 | F29: 87542.37 | G29: 73932.6 | H29: 74021.65 | I29: 78132.75 | J29: 108110.28 | K29: 131636.45 | L29: 139212.56 | M29: 930554.95 | O29: =PROPER(B29) -> Papua Barat
A30: =IFERROR(INDEX(province_power_capacity_2025_ra!$A$2:$A$38,MATCH(B30, province_power_capacity_2025_raw[province],0)),"Data Tidak Ditemukan") -> 96 | B30: PAPUA BARAT DAYA | J30: 58450.28 | K30: 59063.54 | L30: 61624.05 | M30: 179137.87 | O30: =PROPER(B30) -> Papua Barat Daya
A31: =IFERROR(INDEX(province_power_capacity_2025_ra!$A$2:$A$38,MATCH(B31, province_power_capacity_2025_raw[province],0)),"Data Tidak Ditemukan") -> 95 | B31: PAPUA PEGUNUNGAN | J31: 16869.97 | K31: 18105.38 | L31: 19111.44 | M31: 54086.79 | O31: =PROPER(B31) -> Papua Pegunungan
A32: =IFERROR(INDEX(province_power_capacity_2025_ra!$A$2:$A$38,MATCH(B32, province_power_capacity_2025_raw[province],0)),"Data Tidak Ditemukan") -> 93 | B32: PAPUA SELATAN | J32: 58580.68 | K32: 61621.8 | L32: 64928.23 | M32: 185130.71 | O32: =PROPER(B32) -> Papua Selatan
A33: =IFERROR(INDEX(province_power_capacity_2025_ra!$A$2:$A$38,MATCH(B33, province_power_capacity_2025_raw[province],0)),"Data Tidak Ditemukan") -> 94 | B33: PAPUA TENGAH | J33: 103508.09 | K33: 118773.53 | L33: 107565.94 | M33: 329847.56 | O33: =PROPER(B33) -> Papua Tengah
A34: =IFERROR(INDEX(province_power_capacity_2025_ra!$A$2:$A$38,MATCH(B34, province_power_capacity_2025_raw[province],0)),"Data Tidak Ditemukan") -> 14 | B34: RIAU | C34: 104861.11 | D34: 105844.77 | E34: 110384.9 | F34: 111227.01 | G34: 114166.9 | H34: 129740.71 | I34: 151258.97 | J34: 154522.28 | K34: 165349.71 | L34: 176384.66 | M34: 1323741 | O34: =PROPER(B34) -> Riau
A35: =IFERROR(INDEX(province_power_capacity_2025_ra!$A$2:$A$38,MATCH(B35, province_power_capacity_2025_raw[province],0)),"Data Tidak Ditemukan") -> 76 | B35: SULAWESI BARAT | C35: 27513.06 | D35: 29675.86 | E35: 32059.09 | F35: 34111.83 | G35: 32836.75 | H35: 35195.14 | I35: 37033.82 | J35: 39546.78 | K35: 42717.73 | L35: 46653.64 | M35: 357343.7 | O35: =PROPER(B35) -> Sulawesi Barat
A36: =IFERROR(INDEX(province_power_capacity_2025_ra!$A$2:$A$38,MATCH(B36, province_power_capacity_2025_raw[province],0)),"Data Tidak Ditemukan") -> 73 | B36: SULAWESI SELATAN | C36: 43817.39 | D36: 47822.11 | E36: 52642.08 | F36: 57182.14 | G36: 55675.03 | H36: 59502.64 | I36: 65353.29 | J36: 69710.31 | K36: 73573.33 | L36: 78748 | M36: 604026.32 | O36: =PROPER(B36) -> Sulawesi Selatan
A37: =IFERROR(INDEX(province_power_capacity_2025_ra!$A$2:$A$38,MATCH(B37, province_power_capacity_2025_raw[province],0)),"Data Tidak Ditemukan") -> 72 | B37: SULAWESI TENGAH | C37: 41082.04 | D37: 45157.28 | E37: 55518.66 | F37: 61056.03 | G37: 66306.27 | H37: 82016.81 | I37: 106068.47 | J37: 112461.01 | K37: 120749.57 | L37: 131642.52 | M37: 822058.66 | O37: =PROPER(B37) -> Sulawesi Tengah
A38: =IFERROR(INDEX(province_power_capacity_2025_ra!$A$2:$A$38,MATCH(B38, province_power_capacity_2025_raw[province],0)),"Data Tidak Ditemukan") -> 74 | B38: SULAWESI TENGGARA | C38: 38022.13 | D38: 41278.78 | E38: 44492.09 | F38: 48514.15 | G38: 49718.15 | H38: 52436.02 | I38: 58714.73 | J38: 64088.4 | K38: 67839.91 | L38: 72031.18 | M38: 537135.54 | O38: =PROPER(B38) -> Sulawesi Tenggara
A39: =IFERROR(INDEX(province_power_capacity_2025_ra!$A$2:$A$38,MATCH(B39, province_power_capacity_2025_raw[province],0)),"Data Tidak Ditemukan") -> 71 | B39: SULAWESI UTARA | C39: 41246.25 | D39: 44744.2 | E39: 48105.41 | F39: 52173.02 | G39: 50521.13 | H39: 54034.12 | I39: 59020.57 | J39: 64130.96 | K39: 69352.24 | L39: 75234.91 | M39: 558562.81 | O39: =PROPER(B39) -> Sulawesi Utara
A40: =IFERROR(INDEX(province_power_capacity_2025_ra!$A$2:$A$38,MATCH(B40, province_power_capacity_2025_raw[province],0)),"Data Tidak Ditemukan") -> 13 | B40: SUMATERA BARAT | C40: 37284.56 | D40: 40194.29 | E40: 42802.66 | F40: 44885.51 | G40: 43825.66 | H40: 45218.16 | I40: 50263.83 | J40: 54333.83 | K40: 57083.09 | L40: 59548.83 | M40: 475440.42 | O40: =PROPER(B40) -> Sumatera Barat
A41: =IFERROR(INDEX(province_power_capacity_2025_ra!$A$2:$A$38,MATCH(B41, province_power_capacity_2025_raw[province],0)),"Data Tidak Ditemukan") -> 16 | B41: SUMATERA SELATAN | C41: 43361.26 | D41: 46315.05 | E41: 50104.67 | F41: 53359.1 | G41: 53842.74 | H41: 57744.67 | I41: 68238.87 | J41: 71958.27 | K41: 75131.73 | L41: 80663.49 | M41: 600719.85 | O41: =PROPER(B41) -> Sumatera Selatan
A42: =IFERROR(INDEX(province_power_capacity_2025_ra!$A$2:$A$38,MATCH(B42, province_power_capacity_2025_raw[province],0)),"Data Tidak Ditemukan") -> Data Tidak Ditemukan | B42: SUMATERA UTARA | C42: 44392.46 | D42: 48003.6 | E42: 51427.49 | F42: 54620.4 | G42: 54979.04 | H42: 57441.93 | I42: 62922.26 | J42: 68305.71 | K42: 73574.62 | L42: 78310.29 | M42: 593977.8 | O42: =PROPER(B42) -> Sumatera Utara
B43: Grand Total | C43: 1756355.4 | D43: 1892752.8 | E43: 2035134.9 | F43: 2158407.2 | G43: 2110336.3 | H43: 2279805.2 | I43: 2611773.3 | J43: 3024181.6 | K43: 3206337.4 | L43: 3397944.5 | M43: 24473029
O44: =PROPER(B44)

Sheet Final Results
A1: province_code | B1: province | C1: pdrb_per_kapita(2025) | D1: hydro_pp_mw | E1: mini_hydro_pp_mw | F1: micro_hydro_pp_mw | G1: geothermal_pp_mw | H1: solar_pp_mw | I1: wind_pp_mw | J1: biogas_pp_mw | K1: biomass_pp_mw | L1: biofuel_pp_mw | M1: waste_pp_mw | N1: diesel_pp_mw | O1: steam_pp_mw | P1: gas_pp_mw | Q1: coal_gasification_pp_mw | R1: combined_cycle_pp_mw | S1: gas_engine_pp_mw
A2: =IFERROR(INDEX(province_power_capacity_2025_ra!$A$2:$A$38,MATCH(B2, province_power_capacity_2025_raw[province],0)),"Data Tidak Ditemukan") -> 11 | B2: =province_power_capacity_2025_ra!B2 -> Aceh | C2: =_xlfn.XLOOKUP(B2, 'pivot and cleaned data'!$B$5:$B$43, 'pivot and cleaned data'!$L$5:$L$43, "Tidak Ditemukan") -> 45770.4 | D2: =_xlfn.XLOOKUP(B2, province_power_capacity_2025_raw[province], province_power_capacity_2025_raw[hydro_pp_mw], "Tidak Ada") -> 10 | E2: =_xlfn.XLOOKUP(B2, province_power_capacity_2025_raw[province], province_power_capacity_2025_raw[mini_hydro_pp_mw], "Tidak Ada") -> 23.4 | F2: =_xlfn.XLOOKUP(B2, province_power_capacity_2025_raw[province], province_power_capacity_2025_raw[micro_hydro_pp_mw], "Tidak Ada") -> 4.45 | G2: =_xlfn.XLOOKUP(B2, province_power_capacity_2025_raw[province], province_power_capacity_2025_raw[geothermal_pp_mw], "Tidak Ada") -> 0 | H2: =_xlfn.XLOOKUP(B2, province_power_capacity_2025_raw[province], province_power_capacity_2025_raw[solar_pp_mw], "Tidak Ada") -> 1.46 | I2: =_xlfn.XLOOKUP(B2, province_power_capacity_2025_raw[province], province_power_capacity_2025_raw[wind_pp_mw], "Tidak Ada") -> 0 | J2: =_xlfn.XLOOKUP(B2, province_power_capacity_2025_raw[province], province_power_capacity_2025_raw[biogas_pp_mw], "Tidak Ada") -> 0 | K2: =_xlfn.XLOOKUP(B2, province_power_capacity_2025_raw[province], province_power_capacity_2025_raw[biomass_pp_mw], "Tidak Ada") -> 25.1 | L2: =_xlfn.XLOOKUP(B2, province_power_capacity_2025_raw[province], province_power_capacity_2025_raw[biofuel_pp_mw], "Tidak Ada") -> 0 | M2: =_xlfn.XLOOKUP(B2, province_power_capacity_2025_raw[province], province_power_capacity_2025_raw[waste_pp_mw], "Tidak Ada") -> 0 | N2: =_xlfn.XLOOKUP(B2, province_power_capacity_2025_raw[province], province_power_capacity_2025_raw[diesel_pp_mw], "Tidak Ada") -> 218.94 | O2: =_xlfn.XLOOKUP(B2, province_power_capacity_2025_raw[province], province_power_capacity_2025_raw[steam_pp_mw], "Tidak Ada") -> 648 | P2: =_xlfn.XLOOKUP(B2, province_power_capacity_2025_raw[province], province_power_capacity_2025_raw[gas_pp_mw], "Tidak Ada") -> 0 | Q2: =_xlfn.XLOOKUP(B2, province_power_capacity_2025_raw[province], province_power_capacity_2025_raw[coal_gasification_pp_mw], "Tidak Ada") -> 0 | R2: =_xlfn.XLOOKUP(B2, province_power_capacity_2025_raw[province], province_power_capacity_2025_raw[combined_cycle_pp_mw], "Tidak Ada") -> 24 | S2: =_xlfn.XLOOKUP(B2, province_power_capacity_2025_raw[province], province_power_capacity_2025_raw[gas_engine_pp_mw], "Tidak Ada") -> 430.67
A3: =IFERROR(INDEX(province_power_capacity_2025_ra!$A$2:$A$38,MATCH(B3, province_power_capacity_2025_raw[province],0)),"Data Tidak Ditemukan") -> 51 | B3: =province_power_capacity_2025_ra!B3 -> Bali | C3: =_xlfn.XLOOKUP(B3, 'pivot and cleaned data'!$B$5:$B$43, 'pivot and cleaned data'!$L$5:$L$43, "Tidak Ditemukan") -> 72658.49 | D3: =_xlfn.XLOOKUP(B3, province_power_capacity_2025_raw[province], province_power_capacity_2025_raw[hydro_pp_mw], "Tidak Ada") -> 0 | E3: =_xlfn.XLOOKUP(B3, province_power_capacity_2025_raw[province], province_power_capacity_2025_raw[mini_hydro_pp_mw], "Tidak Ada") -> 2.5 | F3: =_xlfn.XLOOKUP(B3, province_power_capacity_2025_raw[province], province_power_capacity_2025_raw[micro_hydro_pp_mw], "Tidak Ada") -> 0.03 | G3: =_xlfn.XLOOKUP(B3, province_power_capacity_2025_raw[province], province_power_capacity_2025_raw[geothermal_pp_mw], "Tidak Ada") -> 0 | H3: =_xlfn.XLOOKUP(B3, province_power_capacity_2025_raw[province], province_power_capacity_2025_raw[solar_pp_mw], "Tidak Ada") -> 41.6 | I3: =_xlfn.XLOOKUP(B3, province_power_capacity_2025_raw[province], province_power_capacity_2025_raw[wind_pp_mw], "Tidak Ada") -> 1.08 | J3: =_xlfn.XLOOKUP(B3, province_power_capacity_2025_raw[province], province_power_capacity_2025_raw[biogas_pp_mw], "Tidak Ada") -> 0 | K3: =_xlfn.XLOOKUP(B3, province_power_capacity_2025_raw[province], province_power_capacity_2025_raw[biomass_pp_mw], "Tidak Ada") -> 0 | L3: =_xlfn.XLOOKUP(B3, province_power_capacity_2025_raw[province], province_power_capacity_2025_raw[biofuel_pp_mw], "Tidak Ada") -> 0 | M3: =_xlfn.XLOOKUP(B3, province_power_capacity_2025_raw[province], province_power_capacity_2025_raw[waste_pp_mw], "Tidak Ada") -> 0 | N3: =_xlfn.XLOOKUP(B3, province_power_capacity_2025_raw[province], province_power_capacity_2025_raw[diesel_pp_mw], "Tidak Ada") -> 127.71 | O3: =_xlfn.XLOOKUP(B3, province_power_capacity_2025_raw[province], province_power_capacity_2025_raw[steam_pp_mw], "Tidak Ada") -> 380 | P3: =_xlfn.XLOOKUP(B3, province_power_capacity_2025_raw[province], province_power_capacity_2025_raw[gas_pp_mw], "Tidak Ada") -> 584.53 | Q3: =_xlfn.XLOOKUP(B3, province_power_capacity_2025_raw[province], province_power_capacity_2025_raw[coal_gasification_pp_mw], "Tidak Ada") -> 0 | R3: =_xlfn.XLOOKUP(B3, province_power_capacity_2025_raw[province], province_power_capacity_2025_raw[combined_cycle_pp_mw], "Tidak Ada") -> 0 | S3: =_xlfn.XLOOKUP(B3, province_power_capacity_2025_raw[province], province_power_capacity_2025_raw[gas_engine_pp_mw], "Tidak Ada") -> 199.66
A4: =IFERROR(INDEX(province_power_capacity_2025_ra!$A$2:$A$38,MATCH(B4, province_power_capacity_2025_raw[province],0)),"Data Tidak Ditemukan") -> 36 | B4: =province_power_capacity_2025_ra!B4 -> Banten | C4: =_xlfn.XLOOKUP(B4, 'pivot and cleaned data'!$B$5:$B$43, 'pivot and cleaned data'!$L$5:$L$43, "Tidak Ditemukan") -> 74672.68 | D4: =_xlfn.XLOOKUP(B4, province_power_capacity_2025_raw[province], province_power_capacity_2025_raw[hydro_pp_mw], "Tidak Ada") -> 0 | E4: =_xlfn.XLOOKUP(B4, province_power_capacity_2025_raw[province], province_power_capacity_2025_raw[mini_hydro_pp_mw], "Tidak Ada") -> 0 | F4: =_xlfn.XLOOKUP(B4, province_power_capacity_2025_raw[province], province_power_capacity_2025_raw[micro_hydro_pp_mw], "Tidak Ada") -> 15.5 | G4: =_xlfn.XLOOKUP(B4, province_power_capacity_2025_raw[province], province_power_capacity_2025_raw[geothermal_pp_mw], "Tidak Ada") -> 0 | H4: =_xlfn.XLOOKUP(B4, province_power_capacity_2025_raw[province], province_power_capacity_2025_raw[solar_pp_mw], "Tidak Ada") -> 91.53 | I4: =_xlfn.XLOOKUP(B4, province_power_capacity_2025_raw[province], province_power_capacity_2025_raw[wind_pp_mw], "Tidak Ada") -> 0 | J4: =_xlfn.XLOOKUP(B4, province_power_capacity_2025_raw[province], province_power_capacity_2025_raw[biogas_pp_mw], "Tidak Ada") -> 0 | K4: =_xlfn.XLOOKUP(B4, province_power_capacity_2025_raw[province], province_power_capacity_2025_raw[biomass_pp_mw], "Tidak Ada") -> 0 | L4: =_xlfn.XLOOKUP(B4, province_power_capacity_2025_raw[province], province_power_capacity_2025_raw[biofuel_pp_mw], "Tidak Ada") -> 0 | M4: =_xlfn.XLOOKUP(B4, province_power_capacity_2025_raw[province], province_power_capacity_2025_raw[waste_pp_mw], "Tidak Ada") -> 0 | N4: =_xlfn.XLOOKUP(B4, province_power_capacity_2025_raw[province], province_power_capacity_2025_raw[diesel_pp_mw], "Tidak Ada") -> 165.53 | O4: =_xlfn.XLOOKUP(B4, province_power_capacity_2025_raw[province], province_power_capacity_2025_raw[steam_pp_mw], "Tidak Ada") -> 11436.44 | P4: =_xlfn.XLOOKUP(B4, province_power_capacity_2025_raw[province], province_power_capacity_2025_raw[gas_pp_mw], "Tidak Ada") -> 80.6 | Q4: =_xlfn.XLOOKUP(B4, province_power_capacity_2025_raw[province], province_power_capacity_2025_raw[coal_gasification_pp_mw], "Tidak Ada") -> 200 | R4: =_xlfn.XLOOKUP(B4, province_power_capacity_2025_raw[province], province_power_capacity_2025_raw[combined_cycle_pp_mw], "Tidak Ada") -> 859.4 | S4: =_xlfn.XLOOKUP(B4, province_power_capacity_2025_raw[province], province_power_capacity_2025_raw[gas_engine_pp_mw], "Tidak Ada") -> 12.25
A5: =IFERROR(INDEX(province_power_capacity_2025_ra!$A$2:$A$38,MATCH(B5, province_power_capacity_2025_raw[province],0)),"Data Tidak Ditemukan") -> 17 | B5: =province_power_capacity_2025_ra!B5 -> Bengkulu | C5: =_xlfn.XLOOKUP(B5, 'pivot and cleaned data'!$B$5:$B$43, 'pivot and cleaned data'!$L$5:$L$43, "Tidak Ditemukan") -> 52304.54 | D5: =_xlfn.XLOOKUP(B5, province_power_capacity_2025_raw[province], province_power_capacity_2025_raw[hydro_pp_mw], "Tidak Ada") -> 277.15 | E5: =_xlfn.XLOOKUP(B5, province_power_capacity_2025_raw[province], province_power_capacity_2025_raw[mini_hydro_pp_mw], "Tidak Ada") -> 42.77 | F5: =_xlfn.XLOOKUP(B5, province_power_capacity_2025_raw[province], province_power_capacity_2025_raw[micro_hydro_pp_mw], "Tidak Ada") -> 2.64 | G5: =_xlfn.XLOOKUP(B5, province_power_capacity_2025_raw[province], province_power_capacity_2025_raw[geothermal_pp_mw], "Tidak Ada") -> 0 | H5: =_xlfn.XLOOKUP(B5, province_power_capacity_2025_raw[province], province_power_capacity_2025_raw[solar_pp_mw], "Tidak Ada") -> 0.41 | I5: =_xlfn.XLOOKUP(B5, province_power_capacity_2025_raw[province], province_power_capacity_2025_raw[wind_pp_mw], "Tidak Ada") -> 0 | J5: =_xlfn.XLOOKUP(B5, province_power_capacity_2025_raw[province], province_power_capacity_2025_raw[biogas_pp_mw], "Tidak Ada") -> 3.3 | K5: =_xlfn.XLOOKUP(B5, province_power_capacity_2025_raw[province], province_power_capacity_2025_raw[biomass_pp_mw], "Tidak Ada") -> 15.04 | L5: =_xlfn.XLOOKUP(B5, province_power_capacity_2025_raw[province], province_power_capacity_2025_raw[biofuel_pp_mw], "Tidak Ada") -> 0 | M5: =_xlfn.XLOOKUP(B5, province_power_capacity_2025_raw[province], province_power_capacity_2025_raw[waste_pp_mw], "Tidak Ada") -> 0 | N5: =_xlfn.XLOOKUP(B5, province_power_capacity_2025_raw[province], province_power_capacity_2025_raw[diesel_pp_mw], "Tidak Ada") -> 21.39 | O5: =_xlfn.XLOOKUP(B5, province_power_capacity_2025_raw[province], province_power_capacity_2025_raw[steam_pp_mw], "Tidak Ada") -> 200 | P5: =_xlfn.XLOOKUP(B5, province_power_capacity_2025_raw[province], province_power_capacity_2025_raw[gas_pp_mw], "Tidak Ada") -> 0 | Q5: =_xlfn.XLOOKUP(B5, province_power_capacity_2025_raw[province], province_power_capacity_2025_raw[coal_gasification_pp_mw], "Tidak Ada") -> 0 | R5: =_xlfn.XLOOKUP(B5, province_power_capacity_2025_raw[province], province_power_capacity_2025_raw[combined_cycle_pp_mw], "Tidak Ada") -> 0 | S5: =_xlfn.XLOOKUP(B5, province_power_capacity_2025_raw[province], province_power_capacity_2025_raw[gas_engine_pp_mw], "Tidak Ada") -> 0
A6: =IFERROR(INDEX(province_power_capacity_2025_ra!$A$2:$A$38,MATCH(B6, province_power_capacity_2025_raw[province],0)),"Data Tidak Ditemukan") -> 34 | B6: =province_power_capacity_2025_ra!B6 -> DI Yogyakarta | C6: =_xlfn.XLOOKUP(B6, 'pivot and cleaned data'!$B$5:$B$43, 'pivot and cleaned data'!$L$5:$L$43, "Tidak Ditemukan") -> 55039.3 | D6: =_xlfn.XLOOKUP(B6, province_power_capacity_2025_raw[province], province_power_capacity_2025_raw[hydro_pp_mw], "Tidak Ada") -> 0 | E6: =_xlfn.XLOOKUP(B6, province_power_capacity_2025_raw[province], province_power_capacity_2025_raw[mini_hydro_pp_mw], "Tidak Ada") -> 0 | F6: =_xlfn.XLOOKUP(B6, province_power_capacity_2025_raw[province], province_power_capacity_2025_raw[micro_hydro_pp_mw], "Tidak Ada") -> 0.5 | G6: =_xlfn.XLOOKUP(B6, province_power_capacity_2025_raw[province], province_power_capacity_2025_raw[geothermal_pp_mw], "Tidak Ada") -> 0 | H6: =_xlfn.XLOOKUP(B6, province_power_capacity_2025_raw[province], province_power_capacity_2025_raw[solar_pp_mw], "Tidak Ada") -> 4.17 | I6: =_xlfn.XLOOKUP(B6, province_power_capacity_2025_raw[province], province_power_capacity_2025_raw[wind_pp_mw], "Tidak Ada") -> 0 | J6: =_xlfn.XLOOKUP(B6, province_power_capacity_2025_raw[province], province_power_capacity_2025_raw[biogas_pp_mw], "Tidak Ada") -> 0 | K6: =_xlfn.XLOOKUP(B6, province_power_capacity_2025_raw[province], province_power_capacity_2025_raw[biomass_pp_mw], "Tidak Ada") -> 3.8 | L6: =_xlfn.XLOOKUP(B6, province_power_capacity_2025_raw[province], province_power_capacity_2025_raw[biofuel_pp_mw], "Tidak Ada") -> 0 | M6: =_xlfn.XLOOKUP(B6, province_power_capacity_2025_raw[province], province_power_capacity_2025_raw[waste_pp_mw], "Tidak Ada") -> 0 | N6: =_xlfn.XLOOKUP(B6, province_power_capacity_2025_raw[province], province_power_capacity_2025_raw[diesel_pp_mw], "Tidak Ada") -> 8.31 | O6: =_xlfn.XLOOKUP(B6, province_power_capacity_2025_raw[province], province_power_capacity_2025_raw[steam_pp_mw], "Tidak Ada") -> 0 | P6: =_xlfn.XLOOKUP(B6, province_power_capacity_2025_raw[province], province_power_capacity_2025_raw[gas_pp_mw], "Tidak Ada") -> 0 | Q6: =_xlfn.XLOOKUP(B6, province_power_capacity_2025_raw[province], province_power_capacity_2025_raw[coal_gasification_pp_mw], "Tidak Ada") -> 0 | R6: =_xlfn.XLOOKUP(B6, province_power_capacity_2025_raw[province], province_power_capacity_2025_raw[combined_cycle_pp_mw], "Tidak Ada") -> 0 | S6: =_xlfn.XLOOKUP(B6, province_power_capacity_2025_raw[province], province_power_capacity_2025_raw[gas_engine_pp_mw], "Tidak Ada") -> 0
